
# Orchestration Validation Report
**Execution ID**: validation_test_1754628106
**Validation Time**: 2025-08-08T14:41:46.864956
**Overall Success**: ❌ FAIL

## Evidence Summary
- **Total Checks**: 12
- **Success Rate**: 16.7%
- **Critical Failures**: 7
- **Validation Quality**: LOW

## Detailed Validation Results

### critical_api_api_health - ❌ FAIL
**Description**: API endpoint api_health connectivity test
**Error**: Failed to connect to http://localhost:8080/health: HTTPConnectionPool(host='localhost', port=8080): Max retries exceeded with url: /health (Caused by NewConnectionError('<urllib3.connection.HTTPConnection object at 0x7531342026f0>: Failed to establish a new connection: [Errno 111] Connection refused'))
**Evidence**: {
  "url": "http://localhost:8080/health",
  "error": "HTTPConnectionPool(host='localhost', port=8080): Max retries exceeded with url: /health (Caused by NewConnectionError('<urllib3.connection.HTTPConnection object at 0x7531342026f0>: Failed to establish a new connection: [Errno 111] Connection refused'))"
}

### critical_api_api_metrics - ❌ FAIL
**Description**: API endpoint api_metrics connectivity test
**Error**: Failed to connect to http://localhost:8080/metrics: HTTPConnectionPool(host='localhost', port=8080): Max retries exceeded with url: /metrics (Caused by NewConnectionError('<urllib3.connection.HTTPConnection object at 0x753134202ea0>: Failed to establish a new connection: [Errno 111] Connection refused'))
**Evidence**: {
  "url": "http://localhost:8080/metrics",
  "error": "HTTPConnectionPool(host='localhost', port=8080): Max retries exceeded with url: /metrics (Caused by NewConnectionError('<urllib3.connection.HTTPConnection object at 0x753134202ea0>: Failed to establish a new connection: [Errno 111] Connection refused'))"
}

### critical_api_auth_metrics - ❌ FAIL
**Description**: API endpoint auth_metrics connectivity test
**Error**: Failed to connect to http://localhost:8080/auth/metrics: HTTPConnectionPool(host='localhost', port=8080): Max retries exceeded with url: /auth/metrics (Caused by NewConnectionError('<urllib3.connection.HTTPConnection object at 0x753134203650>: Failed to establish a new connection: [Errno 111] Connection refused'))
**Evidence**: {
  "url": "http://localhost:8080/auth/metrics",
  "error": "HTTPConnectionPool(host='localhost', port=8080): Max retries exceeded with url: /auth/metrics (Caused by NewConnectionError('<urllib3.connection.HTTPConnection object at 0x753134203650>: Failed to establish a new connection: [Errno 111] Connection refused'))"
}

### critical_api_user_metrics - ❌ FAIL
**Description**: API endpoint user_metrics connectivity test
**Error**: Failed to connect to http://localhost:8080/user/metrics: HTTPConnectionPool(host='localhost', port=8080): Max retries exceeded with url: /user/metrics (Caused by NewConnectionError('<urllib3.connection.HTTPConnection object at 0x753134203e00>: Failed to establish a new connection: [Errno 111] Connection refused'))
**Evidence**: {
  "url": "http://localhost:8080/user/metrics",
  "error": "HTTPConnectionPool(host='localhost', port=8080): Max retries exceeded with url: /user/metrics (Caused by NewConnectionError('<urllib3.connection.HTTPConnection object at 0x753134203e00>: Failed to establish a new connection: [Errno 111] Connection refused'))"
}

### critical_redis_connectivity - ❌ FAIL
**Description**: Redis authentication service connectivity
**Error**: Redis ping failed: 
**Evidence**: {
  "command": "docker exec redis-cli ping",
  "return_code": 0,
  "stdout": "NOAUTH Authentication required.\n\n",
  "stderr": ""
}

### critical_jwt_service - ❌ FAIL
**Description**: JWT authentication service validation
**Error**: JWT service test failed: HTTPConnectionPool(host='localhost', port=8080): Max retries exceeded with url: /auth/health (Caused by NewConnectionError('<urllib3.connection.HTTPConnection object at 0x753134203da0>: Failed to establish a new connection: [Errno 111] Connection refused'))
**Evidence**: {
  "error": "HTTPConnectionPool(host='localhost', port=8080): Max retries exceeded with url: /auth/health (Caused by NewConnectionError('<urllib3.connection.HTTPConnection object at 0x753134203da0>: Failed to establish a new connection: [Errno 111] Connection refused'))"
}

### monitoring_node_exporter - ✅ PASS
**Description**: Node exporter metrics functionality
**Evidence**: {
  "status_code": 200,
  "metrics_count": 2375,
  "sample_metrics": "# HELP go_gc_duration_seconds A summary of the wall-time pause (stop-the-world) duration in garbage collection cycles.\n# TYPE go_gc_duration_seconds summary\ngo_gc_duration_seconds{quantile=\"0\"} 1.3207e-05\ngo_gc_duration_seconds{quantile=\"0.25\"} 2.6907e-05\ngo_gc_duration_seconds{quantile=\"0.5\"} 3.563"
}

### monitoring_grafana - ❌ FAIL
**Description**: Grafana dashboard service
**Error**: Grafana test failed: ('Connection aborted.', RemoteDisconnected('Remote end closed connection without response'))
**Evidence**: {
  "error": "('Connection aborted.', RemoteDisconnected('Remote end closed connection without response'))"
}

### critical_postgres_connectivity - ❌ FAIL
**Description**: PostgreSQL database connectivity
**Error**: PostgreSQL test failed: psql: error: connection to server on socket "/var/run/postgresql/.s.PGSQL.5432" failed: FATAL:  role "ai_workflow_user" does not exist

**Evidence**: {
  "command": "psql SELECT 1",
  "return_code": 2,
  "stdout": "",
  "stderr": "psql: error: connection to server on socket \"/var/run/postgresql/.s.PGSQL.5432\" failed: FATAL:  role \"ai_workflow_user\" does not exist\n"
}

### service_integration_health - ✅ PASS
**Description**: Docker container health status
**Evidence**: {
  "container_status": "NAMES                                      STATUS\nai_workflow_engine-caddy_reverse_proxy-1   Up 15 hours (healthy)\nai_workflow_engine-webui-1                 Up 8 hours\nai_workflow_engine-worker-1                Up 14 hours (healthy)\nai_workflow_engine-api-1                   Up 6 hours (healthy)\nai_workflow_engine-pgbouncer_exporter-1    Up 15 hours (healthy)\nai_workflow_engine-kibana-1                Up 15 hours (healthy)\nai_workflow_engine-postgres_exporter-1     Up 15 hours (healthy)\nai_workflow_engine-fluent_bit-1            Up 14 hours\nai_workflow_engine-grafana-1               Up 15 hours (healthy)\nai_workflow_engine-promtail-1              Up 14 hours\nai_workflow_engine-alertmanager-1          Up 15 hours (healthy)\nai_workflow_engine-redis_exporter-1        Up 15 hours (healthy)\nai_workflow_engine-redis-1                 Up 15 hours (healthy)\nai_workflow_engine-log-watcher-1           Up 15 hours\nai_workflow_engine-pgbouncer-1             Up 15 hours (healthy)\nai_workflow_engine-qdrant-1                Up 15 hours (healthy)\nai_workflow_engine-prometheus-1            Up 15 hours (healthy)\nai_workflow_engine-elasticsearch-1         Up 15 hours (healthy)\nai_workflow_engine-cadvisor-1              Up 15 hours (healthy)\nai_workflow_engine-loki-1                  Up 14 hours (healthy)\nai_workflow_engine-blackbox_exporter-1     Up 15 hours (healthy)\nai_workflow_engine-jaeger-1                Up 15 hours (healthy)\nai_workflow_engine-node_exporter-1         Up 15 hours (healthy)\nai_workflow_engine-ollama-1                Up 15 hours (healthy)\nai_workflow_engine-postgres-1              Up 15 hours (healthy)\nredis-mcp                                  Up 3 days (healthy)\n",
  "unhealthy_containers": []
}

### evidence_agent1 - ❌ FAIL
**Description**: Evidence validation for agent1
**Error**: Missing evidence: ['error_handling_tests', 'integration_flow_tests', 'api_contract_compliance']
**Evidence**: {
  "required_evidence": [
    "endpoint_response_validation",
    "error_handling_tests",
    "integration_flow_tests",
    "api_contract_compliance"
  ],
  "provided_evidence": [
    "endpoint_response_validation"
  ],
  "missing_evidence": [
    "error_handling_tests",
    "integration_flow_tests",
    "api_contract_compliance"
  ],
  "task_type": "api_implementations"
}

### evidence_agent2 - ❌ FAIL
**Description**: Evidence validation for agent2
**Error**: Missing evidence: ['redis_connectivity_proof', 'jwt_validation_success', 'login_flow_completion', 'auth_endpoint_responses']
**Evidence**: {
  "required_evidence": [
    "redis_connectivity_proof",
    "jwt_validation_success",
    "login_flow_completion",
    "auth_endpoint_responses"
  ],
  "provided_evidence": [],
  "missing_evidence": [
    "redis_connectivity_proof",
    "jwt_validation_success",
    "login_flow_completion",
    "auth_endpoint_responses"
  ],
  "task_type": "authentication_fixes"
}

## Required Iterations
- Phase 2.5 - Fix critical infrastructure failures
- Phase 4 - Address validation failures
